Workbook

Sheet Scenarios
A1: DEXTER SPORTS CO.
A2: Scenario Selector — Base vs. Upside
A3: Type 1 for Base or 2 for Upside in the gold cell. Inputs and Proforma update automatically.
A5: SELECTED SCENARIO (1=Base, 2=Upside): | B5: 1 | C5: =IF(B5=2,"▶ UPSIDE CASE ACTIVE","▶ BASE CASE ACTIVE") -> ▶ BASE CASE ACTIVE
A7: Placement Driver | B7: Base | C7: Upside | D7: Selected →
A8: Placements — Year 1 | B8: 20 | C8: 30 | D8: =IF($B$5=2,C8,B8) -> 20
A9: Placement growth rate (Y/Y) | B9: 0.15 | C9: 0.2 | D9: =IF($B$5=2,C9,B9) -> 0.15
A10: Avg. coach salary placed | B10: 120000 | C10: 150000 | D10: =IF($B$5=2,C10,B10) -> 120000
A11: Salary growth rate (Y/Y) | B11: 0.03 | C11: 0.04 | D11: =IF($B$5=2,C11,B11) -> 0.03
A12: Placement fee (% of salary) | B12: 0.03 | C12: 0.03 | D12: =IF($B$5=2,C12,B12) -> 0.03
A13: Collection rate | B13: 0.95 | C13: 0.95 | D13: =IF($B$5=2,C13,B13) -> 0.95
A14: Travel & entertainment / placement | B14: 2500 | C14: 2500 | D14: =IF($B$5=2,C14,B14) -> 2500
A15: Team compensation — Year 1 | B15: 150000 | C15: 220000 | D15: =IF($B$5=2,C15,B15) -> 150000
A16: Minimum fee per placement (floor) | B16: 6000 | C16: 6000 | D16: =IF($B$5=2,C16,B16) -> 6000
A18: Base = measured volume. Upside = more placements + modestly higher salary.
A19: Non-placement drivers (sponsorship, search desk, G&A, expansions) are set on the Inputs tab, shared across scenarios.

Sheet Inputs
A1: DEXTER SPORTS CO.
A2: Key Data Inputs — Kim's Control Panel
A3: Gold cells = edit here. Green cells (placement drivers) are set on the Scenarios tab.
A5: Input | B5: Value | C5: Guidance
A6: REVENUE DRIVERS — COACH PLACEMENT
A7: Placements — Year 1 | B7: =Scenarios!D8 -> 20 | C7: Set on Scenarios tab (Base/Upside)
A8: Placement growth rate (Y/Y) | B8: =Scenarios!D9 -> 0.15 | C8: Set on Scenarios tab
A9: Avg. coach salary placed | B9: =Scenarios!D10 -> 120000 | C9: Set on Scenarios tab
A10: Salary growth rate (Y/Y) | B10: =Scenarios!D11 -> 0.03 | C10: Set on Scenarios tab
A11: Placement fee (% of salary) | B11: =Scenarios!D12 -> 0.03 | C11: Set on Scenarios tab; ~3% market rate
A12: Collection rate | B12: =Scenarios!D13 -> 0.95 | C12: Set on Scenarios tab
A13: Minimum fee per placement (floor) | B13: =Scenarios!D16 -> 6000 | C13: MAX(3% of salary, floor) per hire — floor binds at these salaries
A14: COST DRIVERS — CORE
A15: Travel & entertainment / placement | B15: =Scenarios!D14 -> 2500 | C15: Set on Scenarios tab
A16: Sponsorship spend — Year 1 | B16: 40000 | C16: Event/athlete sponsorships, Year 1
A17: Sponsorship growth (Y/Y) | B17: 0.15 | C17: Annual growth
A18: Marketing & BD (% of revenue) | B18: 0.05 | C18: Brand, outreach, content
A19: Team compensation — Year 1 | B19: =Scenarios!D15 -> 150000 | C19: Set on Scenarios tab
A20: Staff comp growth (Y/Y) | B20: 0.1 | C20: Annual comp growth
A21: G&A / overhead — Year 1 | B21: 30000 | C21: Legal, software, insurance, admin
A22: G&A growth (Y/Y) | B22: 0.05 | C22: Annual overhead growth
A23: Effective tax rate | B23: 0.21 | C23: Blended income tax rate
A24: EXPANSION 3 — SCHOOL-PAID SEARCH DESK
A25: Search desk active? (1=on, 0=off) | B25: 0 | C25: Flat-fee searches for mid-major/D-II/D-III, paid by schools
A26: Search — launch year (1-5) | B26: 2 | C26: Year the search desk begins
A27: Searches — launch year | B27: 4 | C27: # of school-paid searches at launch
A28: Search growth (Y/Y) | B28: 0.3 | C28: Annual growth in searches
A29: Avg. fee per search | B29: 15000 | C29: Flat fee; priced below big firms ($25K–120K)
A30: Search collection rate | B30: 0.95 | C30: % of search fees collected
A31: Search cost / engagement | B31: 2000 | C31: Candidate sourcing, travel per search
A32: EXPANSION 1 — NFLPA AGENT REP (placeholder)
A33: NFLPA line active? (1=on, 0=off) | B33: 0 | C33: Toggle on once Kim is NFLPA certified
A34: NFLPA — launch year (1-5) | B34: 3 | C34: Year service goes live
A35: NFLPA — clients at launch | B35: 3 | C35: NFL players represented at launch
A36: NFLPA — client growth (Y/Y) | B36: 0.3 | C36: Annual roster growth
A37: NFLPA — avg. contract value | B37: 1500000 | C37: Avg annual contract represented
A38: NFLPA — commission (% contract) | B38: 0.03 | C38: NFLPA cap is 3%
A39: NFLPA — collection rate | B39: 0.95 | C39: % of commissions collected
A40: NFLPA — cost / client | B40: 8000 | C40: Travel, compliance, servicing
A41: EXPANSION 2 — NIL SERVICES (NC/SC HS athletes)
...

Sheet Assumptions
A1: Assumptions (driven by Inputs tab) | C1: → Edit values on the Inputs tab, not here.
A4: INPUT | B4: Value | C4: Notes
A5: REVENUE DRIVERS — COACH PLACEMENT
A6: Placements — Year 1 | B6: =Inputs!B7 -> 20
A7: Placement growth rate (Y/Y) | B7: =Inputs!B8 -> 0.15
A8: Avg. coach salary placed | B8: =Inputs!B9 -> 120000
A9: Salary growth rate (Y/Y) | B9: =Inputs!B10 -> 0.03
A10: Placement fee (% of salary) | B10: =Inputs!B11 -> 0.03
A11: Collection rate | B11: =Inputs!B12 -> 0.95
A12: Minimum fee per placement (floor) | B12: =Inputs!B13 -> 6000
A13: COST DRIVERS — CORE
A14: Travel & entertainment / placement | B14: =Inputs!B15 -> 2500
A15: Sponsorship spend — Year 1 | B15: =Inputs!B16 -> 40000
A16: Sponsorship growth (Y/Y) | B16: =Inputs!B17 -> 0.15
A17: Marketing & BD (% of revenue) | B17: =Inputs!B18 -> 0.05
A18: Team compensation — Year 1 | B18: =Inputs!B19 -> 150000
A19: Staff comp growth (Y/Y) | B19: =Inputs!B20 -> 0.1
A20: G&A / overhead — Year 1 | B20: =Inputs!B21 -> 30000
A21: G&A growth (Y/Y) | B21: =Inputs!B22 -> 0.05
A22: Effective tax rate | B22: =Inputs!B23 -> 0.21
A23: EXPANSION 3 — SCHOOL-PAID SEARCH DESK
A24: Search desk active? (1=on, 0=off) | B24: =Inputs!B25 -> 0
A25: Search — launch year (1-5) | B25: =Inputs!B26 -> 2
A26: Searches — launch year | B26: =Inputs!B27 -> 4
A27: Search growth (Y/Y) | B27: =Inputs!B28 -> 0.3
A28: Avg. fee per search | B28: =Inputs!B29 -> 15000
A29: Search collection rate | B29: =Inputs!B30 -> 0.95
A30: Search cost / engagement | B30: =Inputs!B31 -> 2000
A31: EXPANSION 1 — NFLPA AGENT REP
A32: NFLPA line active? (1=on, 0=off) | B32: =Inputs!B33 -> 0
A33: NFLPA — launch year (1-5) | B33: =Inputs!B34 -> 3
A34: NFLPA — clients at launch | B34: =Inputs!B35 -> 3
A35: NFLPA — client growth (Y/Y) | B35: =Inputs!B36 -> 0.3
A36: NFLPA — avg. contract value | B36: =Inputs!B37 -> 1500000
A37: NFLPA — commission (% contract) | B37: =Inputs!B38 -> 0.03
A38: NFLPA — collection rate | B38: =Inputs!B39 -> 0.95
A39: NFLPA — cost / client | B39: =Inputs!B40 -> 8000
A40: EXPANSION 2 — NIL SERVICES (NC/SC HS)
A41: NIL line active? (1=on, 0=off) | B41: =Inputs!B42 -> 0
A42: NIL — launch year (1-5) | B42: =Inputs!B43 -> 2
...

Sheet Proforma P&L
A1: DEXTER SPORTS CO. — 5-Year Proforma P&L
A2: Coach placement + school-paid search desk, NFLPA agent rep & NC/SC NIL (all toggleable)
A4: Line Item | B4: Year 1 | C4: Year 2 | D4: Year 3 | E4: Year 4 | F4: Year 5
A5: OPERATING METRICS — COACH PLACEMENT
A6: Coaches placed | B6: =Assumptions!$B$6 -> 20 | C6: =B6*(1+Assumptions!$B$7) -> 23 | D6: =C6*(1+Assumptions!$B$7) -> 26.45 | E6: =D6*(1+Assumptions!$B$7) -> 30.4175 | F6: =E6*(1+Assumptions!$B$7) -> 34.980125
A7: Avg. salary placed | B7: =Assumptions!$B$8 -> 120000 | C7: =B7*(1+Assumptions!$B$9) -> 123600 | D7: =C7*(1+Assumptions!$B$9) -> 127308 | E7: =D7*(1+Assumptions!$B$9) -> 131127.24 | F7: =E7*(1+Assumptions!$B$9) -> 135061.06
A9: REVENUE
A10: Coach placement fees | B10: =B6*MAX(B7*Assumptions!$B$10,Assumptions!$B$12)*Assumptions!$B$11 -> 114000 | C10: =C6*MAX(C7*Assumptions!$B$10,Assumptions!$B$12)*Assumptions!$B$11 -> 131100 | D10: =D6*MAX(D7*Assumptions!$B$10,Assumptions!$B$12)*Assumptions!$B$11 -> 150765 | E10: =E6*MAX(E7*Assumptions!$B$10,Assumptions!$B$12)*Assumptions!$B$11 -> 173379.75 | F10: =F6*MAX(F7*Assumptions!$B$10,Assumptions!$B$12)*Assumptions!$B$11 -> 199386.71
A11: Searches (active yrs) | B11: =IF(AND(Assumptions!$B$24=1,1>=Assumptions!$B$25),Assumptions!$B$26*(1+Assumptions!$B$27)^(1-Assumptions!$B$25),0) -> 0 | C11: =IF(AND(Assumptions!$B$24=1,2>=Assumptions!$B$25),Assumptions!$B$26*(1+Assumptions!$B$27)^(2-Assumptions!$B$25),0) -> 0 | D11: =IF(AND(Assumptions!$B$24=1,3>=Assumptions!$B$25),Assumptions!$B$26*(1+Assumptions!$B$27)^(3-Assumptions!$B$25),0) -> 0 | E11: =IF(AND(Assumptions!$B$24=1,4>=Assumptions!$B$25),Assumptions!$B$26*(1+Assumptions!$B$27)^(4-Assumptions!$B$25),0) -> 0 | F11: =IF(AND(Assumptions!$B$24=1,5>=Assumptions!$B$25),Assumptions!$B$26*(1+Assumptions!$B$27)^(5-Assumptions!$B$25),0) -> 0
A12: School-paid search fees | B12: =B11*Assumptions!$B$28*Assumptions!$B$29 -> 0 | C12: =C11*Assumptions!$B$28*Assumptions!$B$29 -> 0 | D12: =D11*Assumptions!$B$28*Assumptions!$B$29 -> 0 | E12: =E11*Assumptions!$B$28*Assumptions!$B$29 -> 0 | F12: =F11*Assumptions!$B$28*Assumptions!$B$29 -> 0
A13: NFLPA — clients (active yrs) | B13: =IF(AND(Assumptions!$B$32=1,1>=Assumptions!$B$33),Assumptions!$B$34*(1+Assumptions!$B$35)^(1-Assumptions!$B$33),0) -> 0 | C13: =IF(AND(Assumptions!$B$32=1,2>=Assumptions!$B$33),Assumptions!$B$34*(1+Assumptions!$B$35)^(2-Assumptions!$B$33),0) -> 0 | D13: =IF(AND(Assumptions!$B$32=1,3>=Assumptions!$B$33),Assumptions!$B$34*(1+Assumptions!$B$35)^(3-Assumptions!$B$33),0) -> 0 | E13: =IF(AND(Assumptions!$B$32=1,4>=Assumptions!$B$33),Assumptions!$B$34*(1+Assumptions!$B$35)^(4-Assumptions!$B$33),0) -> 0 | F13: =IF(AND(Assumptions!$B$32=1,5>=Assumptions!$B$33),Assumptions!$B$34*(1+Assumptions!$B$35)^(5-Assumptions!$B$33),0) -> 0
A14: NFLPA agent commissions | B14: =B13*Assumptions!$B$36*Assumptions!$B$37*Assumptions!$B$38 -> 0 | C14: =C13*Assumptions!$B$36*Assumptions!$B$37*Assumptions!$B$38 -> 0 | D14: =D13*Assumptions!$B$36*Assumptions!$B$37*Assumptions!$B$38 -> 0 | E14: =E13*Assumptions!$B$36*Assumptions!$B$37*Assumptions!$B$38 -> 0 | F14: =F13*Assumptions!$B$36*Assumptions!$B$37*Assumptions!$B$38 -> 0
A15: NIL — athletes (active yrs) | B15: =IF(AND(Assumptions!$B$41=1,1>=Assumptions!$B$42),Assumptions!$B$43*(1+Assumptions!$B$44)^(1-Assumptions!$B$42),0) -> 0 | C15: =IF(AND(Assumptions!$B$41=1,2>=Assumptions!$B$42),Assumptions!$B$43*(1+Assumptions!$B$44)^(2-Assumptions!$B$42),0) -> 0 | D15: =IF(AND(Assumptions!$B$41=1,3>=Assumptions!$B$42),Assumptions!$B$43*(1+Assumptions!$B$44)^(3-Assumptions!$B$42),0) -> 0 | E15: =IF(AND(Assumptions!$B$41=1,4>=Assumptions!$B$42),Assumptions!$B$43*(1+Assumptions!$B$44)^(4-Assumptions!$B$42),0) -> 0 | F15: =IF(AND(Assumptions!$B$41=1,5>=Assumptions!$B$42),Assumptions!$B$43*(1+Assumptions!$B$44)^(5-Assumptions!$B$42),0) -> 0
A16: NIL service fees (NC/SC HS) | B16: =B15*Assumptions!$B$45*Assumptions!$B$46*Assumptions!$B$47 -> 0 | C16: =C15*Assumptions!$B$45*Assumptions!$B$46*Assumptions!$B$47 -> 0 | D16: =D15*Assumptions!$B$45*Assumptions!$B$46*Assumptions!$B$47 -> 0 | E16: =E15*Assumptions!$B$45*Assumptions!$B$46*Assumptions!$B$47 -> 0 | F16: =F15*Assumptions!$B$45*Assumptions!$B$46*Assumptions!$B$47 -> 0
A17: Total net revenue | B17: =B10+B12+B14+B16 -> 114000 | C17: =C10+C12+C14+C16 -> 131100 | D17: =D10+D12+D14+D16 -> 150765 | E17: =E10+E12+E14+E16 -> 173379.75 | F17: =F10+F12+F14+F16 -> 199386.71
A19: OPERATING EXPENSES
A20: Travel & entertainment | B20: =B6*Assumptions!$B$14 -> 50000 | C20: =C6*Assumptions!$B$14 -> 57500 | D20: =D6*Assumptions!$B$14 -> 66125 | E20: =E6*Assumptions!$B$14 -> 76043.75 | F20: =F6*Assumptions!$B$14 -> 87450.312
A21: Sponsorships | B21: =Assumptions!$B$15 -> 40000 | C21: =B21*(1+Assumptions!$B$16) -> 46000 | D21: =C21*(1+Assumptions!$B$16) -> 52900 | E21: =D21*(1+Assumptions!$B$16) -> 60835 | F21: =E21*(1+Assumptions!$B$16) -> 69960.25
A22: Marketing & BD | B22: =B17*Assumptions!$B$17 -> 5700 | C22: =C17*Assumptions!$B$17 -> 6555 | D22: =D17*Assumptions!$B$17 -> 7538.25 | E22: =E17*Assumptions!$B$17 -> 8668.9875 | F22: =F17*Assumptions!$B$17 -> 9969.3356
A23: Team compensation | B23: =Assumptions!$B$18 -> 150000 | C23: =B23*(1+Assumptions!$B$19) -> 165000 | D23: =C23*(1+Assumptions!$B$19) -> 181500 | E23: =D23*(1+Assumptions!$B$19) -> 199650 | F23: =E23*(1+Assumptions!$B$19) -> 219615
A24: G&A / overhead | B24: =Assumptions!$B$20 -> 30000 | C24: =B24*(1+Assumptions!$B$21) -> 31500 | D24: =C24*(1+Assumptions!$B$21) -> 33075 | E24: =D24*(1+Assumptions!$B$21) -> 34728.75 | F24: =E24*(1+Assumptions!$B$21) -> 36465.188
A25: Search desk — engagement cost | B25: =B11*Assumptions!$B$30 -> 0 | C25: =C11*Assumptions!$B$30 -> 0 | D25: =D11*Assumptions!$B$30 -> 0 | E25: =E11*Assumptions!$B$30 -> 0 | F25: =F11*Assumptions!$B$30 -> 0
A26: NFLPA — servicing cost | B26: =B13*Assumptions!$B$39 -> 0 | C26: =C13*Assumptions!$B$39 -> 0 | D26: =D13*Assumptions!$B$39 -> 0 | E26: =E13*Assumptions!$B$39 -> 0 | F26: =F13*Assumptions!$B$39 -> 0
A27: NIL — platform + fixed cost | B27: =B15*Assumptions!$B$48+IF(B15>0,Assumptions!$B$49,0) -> 0 | C27: =C15*Assumptions!$B$48+IF(C15>0,Assumptions!$B$49,0) -> 0 | D27: =D15*Assumptions!$B$48+IF(D15>0,Assumptions!$B$49,0) -> 0 | E27: =E15*Assumptions!$B$48+IF(E15>0,Assumptions!$B$49,0) -> 0 | F27: =F15*Assumptions!$B$48+IF(F15>0,Assumptions!$B$49,0) -> 0
A28: Total operating expenses | B28: =SUM(B20:B27) -> 275700 | C28: =SUM(C20:C27) -> 306555 | D28: =SUM(D20:D27) -> 341138.25 | E28: =SUM(E20:E27) -> 379926.49 | F28: =SUM(F20:F27) -> 423460.09
A30: PROFITABILITY
A31: EBITDA | B31: =B17-B28 -> -161700 | C31: =C17-C28 -> -175455 | D31: =D17-D28 -> -190373.25 | E31: =E17-E28 -> -206546.74 | F31: =F17-F28 -> -224073.37
A32: EBITDA margin | B32: =IF(B17=0,0,B31/B17) -> -1.4184211 | C32: =IF(C17=0,0,C31/C17) -> -1.3383295 | D32: =IF(D17=0,0,D31/D17) -> -1.2627152 | E32: =IF(E17=0,0,E31/E17) -> -1.1912968 | F32: =IF(F17=0,0,F31/F17) -> -1.123813
A33: Income tax | B33: =MAX(0,B31)*Assumptions!$B$22 -> 0 | C33: =MAX(0,C31)*Assumptions!$B$22 -> 0 | D33: =MAX(0,D31)*Assumptions!$B$22 -> 0 | E33: =MAX(0,E31)*Assumptions!$B$22 -> 0 | F33: =MAX(0,F31)*Assumptions!$B$22 -> 0
A34: Net income | B34: =B31-B33 -> -161700 | C34: =C31-C33 -> -175455 | D34: =D31-D33 -> -190373.25 | E34: =E31-E33 -> -206546.74 | F34: =F31-F33 -> -224073.37

Sheet Summary
A1: Executive Summary — Snapshot
A2: Base case shown with expansions OFF. Toggle search desk, NFLPA & NIL on the Inputs tab.
A4: Year 5 total net revenue | B4: ='Proforma P&L'!F17 -> 199386.71
A5: Year 5 EBITDA | B5: ='Proforma P&L'!F31 -> -224073.37
A6: Year 5 EBITDA margin | B6: ='Proforma P&L'!F32 -> -1.123813
A7: Year 5 net income | B7: ='Proforma P&L'!F34 -> -224073.37
A8: Coaches placed (Y5) | B8: ='Proforma P&L'!F6 -> 34.980125
A9: Cumulative net income (Y1–Y5) | B9: =SUM('Proforma P&L'!B34:F34) -> -958148.36
A10: Rev — placement (Y5) | B10: ='Proforma P&L'!F10 -> 199386.71
A11: Rev — search desk (Y5) | B11: ='Proforma P&L'!F12 -> 0
A12: Rev — NFLPA (Y5) | B12: ='Proforma P&L'!F14 -> 0
A13: Rev — NIL (Y5) | B13: ='Proforma P&L'!F16 -> 0
